<?xml version="1.0" ?>
<!-- =================================================================================== -->
<!-- |    This document was autogenerated by xacro from ur5_robot.urdf.xacro           | -->
<!-- |    EDITING THIS FILE BY HAND IS NOT RECOMMENDED                                 | -->
<!-- |    Forked from: https://github.com/cpaxton/universal_robot                      | -->
<!-- |    Origin from: https://github.com/ros-industrial/universal_robot               | -->
<!-- =================================================================================== -->
<robot name="universal-robot-ur5" xmlns:controller="http://playerstage.sourceforge.net/gazebo/xmlschema/#controller" xmlns:interface="http://playerstage.sourceforge.net/gazebo/xmlschema/#interface" xmlns:sensor="http://playerstage.sourceforge.net/gazebo/xmlschema/#sensor" xmlns:xacro="http://ros.org/wiki/xacro">
  
  <gazebo>
     <plugin name="gazebo_ros_control" filename="libgazebo_ros_control.so">
       <robotNamespace>/</robotNamespace>
     </plugin>
   </gazebo>
  <material name="UR/Blue">
    <color rgba="0.0 0.0 0.8 1.0"/>
  </material>
  <material name="UR/Grey">
    <color rgba="0.7 0.7 0.7 1.0"/>
  </material>
 

<!-- world -->
  <!-- Used for fixing robots 'base_link' to Gazebos 'world' -->
  <link name="world"/>
  <joint name="rear_camera_joint" type="fixed">
    <parent link="world"/> <!-- Or whatever link you want to attach the camera to -->
    <child link="rear_camera_link"/>
    <origin xyz="-1.0 0 1.8" rpy="0 0.2967 0"/> <!-- Adjust position and orientation -->
  </joint>
  <link name="rear_camera_link">
  <visual>
    <geometry>
      <box size="0.1 0.1 0.1"/>  <!-- Size of the camera -->
    </geometry>
    <material name="camera_material"> 
      <color rgba="0.5 0.5 0.5 1"/>  <!-- Color of the camera -->
    </material>
  </visual>
  <collision>
    <geometry>
      <box size="0.1 0.1 0.1"/>  <!-- Collision box size, usually same as visual -->
    </geometry>
  </collision>
  <inertial>
    <mass value="0.1"/>  <!-- Mass in kilograms -->
    <origin xyz="0 0 0" rpy="0 0 0"/>  <!-- Center of mass -->
    <inertia ixx="0.0001" ixy="0" ixz="0" iyy="0.0001" iyz="0" izz="0.0001"/>
    <!-- Inertia tensor components -->
  </inertial>
  </link>
  <gazebo reference="rear_camera_link">
    <sensor type="camera" name="rear_camera_sensor">
      <update_rate>30.0</update_rate> <!-- Camera update rate in Hz -->
      <visualize>true</visualize>
      <camera name="head">
        <horizontal_fov>1.3962634</horizontal_fov> <!-- Field of view -->
        <image>
          <width>640</width>
          <height>480</height>
          <format>R8G8B8</format>
        </image>
        <clip>
          <near>0.02</near>
          <far>300</far>
        </clip>
      </camera>
      <plugin name="camera_controller" filename="libgazebo_ros_camera.so">
        <alwaysOn>true</alwaysOn>
        <updateRate>0</updateRate>
        <cameraName>rear_camera</cameraName>
        <imageTopicName>rear_camera/image_raw</imageTopicName>
        <cameraInfoTopicName>rear_camera/camera_info</cameraInfoTopicName>
        <frameName>rear_camera_link</frameName>
      </plugin>
    </sensor>
  </gazebo>
  <joint name="world_base_joint" type="fixed">
    <parent link="world"/>
    <child link="base_link"/>
    <origin rpy="0.0 0.0 0.0" xyz="0.0 0.0 1.02"/>
  </joint>
<!-- arm -->
  <link name="base_link">
    <visual>
      <geometry>
        <mesh filename="package://interbotix_xsarm_descriptions/meshes/ur5/visual/Base.dae"/>
      </geometry>
      <origin rpy="0.0 0.0 2.3561944875" xyz="0.0 0.0 0.0"/>
    </visual>
    <collision>
      <geometry>
        <mesh filename="package://interbotix_xsarm_descriptions/meshes/ur5/collision/Base.dae"/>
      </geometry>
      <!-- <origin rpy="0.0 0.0 0.0" xyz="0.0 0.0 -0.009159"/> -->
    </collision>
    <inertial>
      <mass value="4.0"/>
      <inertia ixx="0.004433" ixy="0.0" ixz="0.0" iyy="0.00443333156" iyz="0.0" izz="0.0072"/>
    </inertial>
  </link> 
<!-- <inertia ixx="0.0833333 * 4.0 * (3 * 0.06 * 0.06 + 0.05 * 0.05)" ixy="0.0" ixz="0.0"
        iyy="0.0833333 * 4.0 * (3 * 0.06 * 0.06 + 0.05 * 0.05)" iyz="0.0"
        izz="0.5 * 4.0 * 0.06 * 0.06" /> -->
  <joint name="shoulder_pan_joint" type="revolute">
    <parent link="base_link"/>
    <child link="shoulder_link"/>
    <origin rpy="0.0 0.0 0.0" xyz="0.0 0.0 0.089159"/>
    <axis xyz="0 0 1"/>
    <limit effort="150.0" lower="-6.2831853" upper="6.2831853" velocity="3.14159265"/>
    <dynamics damping="0.0" friction="0.0"/>
  </joint>
  <transmission name="trans_pan_shoulder">
    <type>transmission_interface/SimpleTransmission</type>
    <joint name="shoulder_pan_joint">
      <hardwareInterface>hardware_interface/PositionJointInterface</hardwareInterface>
    </joint>
    <actuator name="shoulder_pan_motor">
      <mechanicalReduction>1</mechanicalReduction>
    </actuator>
  </transmission>
  <link name="shoulder_link">
    <visual>
      <geometry>
        <mesh filename="package://interbotix_xsarm_descriptions/meshes/ur5/visual/Shoulder.dae"/>
      </geometry>
    </visual>
    <collision>
      <geometry>
        <mesh filename="package://interbotix_xsarm_descriptions/meshes/ur5/collision/Shoulder.dae"/>
      </geometry>
      <!-- <origin rpy="0.0 0.0 0.0" xyz="0.0 0.0 -0.009159"/> -->
    </collision>
    <inertial>
      <mass value="3.7"/>
      <inertia ixx="0.010267495893" ixy="0.0" ixz="0.0" iyy="0.010267495893" iyz="0.0" izz="0.00666"/>
 	    <origin rpy="0.0 0.0 0.0" xyz="0.0 0.00193 -0.02561"/>
    </inertial>
  </link>
<!--<inertia ixx="0.0833333 * 3.7 * (3 * 0.06 * 0.06 + 0.15 * 0.15)" ixy="0.0" ixz="0.0"
        iyy="0.0833333 * 3.7 * (3 * 0.06 * 0.06 + 0.15 * 0.15)" iyz="0.0"
        izz="0.5 * 3.7 * 0.06 * 0.06" /> -->
  <joint name="shoulder_lift_joint" type="revolute">
    <parent link="shoulder_link"/>
    <child link="upper_arm_link"/>
    <origin rpy="0.0 0.0 0.0" xyz="0.0 0.13585 0.0"/>
    <axis xyz="0 1 0"/>
    <limit effort="150.0" lower="-6.2831853" upper="6.2831853" velocity="3.14159265"/>
    <dynamics damping="0.0" friction="0.0"/>
  </joint>
  <transmission name="trans_lift_shoulder">
    <type>transmission_interface/SimpleTransmission</type>
    <joint name="shoulder_lift_joint">
      <hardwareInterface>hardware_interface/PositionJointInterface</hardwareInterface>
    </joint>
    <actuator name="shoulder_lift_motor">
      <mechanicalReduction>1</mechanicalReduction>
    </actuator>
  </transmission>
  <link name="upper_arm_link">
    <visual>
      <geometry>
        <mesh filename="package://interbotix_xsarm_descriptions/meshes/ur5/visual/UpperArm.dae"/>
      </geometry>
      <origin rpy="0.0 0.0 0.0" xyz="0.0 0.0 0.0"/>
    </visual>
    <collision>
      <geometry>
        <mesh filename="package://interbotix_xsarm_descriptions/meshes/ur5/collision/UpperArm.dae"/>
      </geometry>
      <!--       <origin rpy="0.0 0.0 0.0" xyz="0.0 0.0 0.2125"/> -->
    </collision>
    <inertial>
      <mass value="8.393"/>
      <inertia ixx="0.22689067591036" ixy="0.0" ixz="0.0" iyy="0.22689067591036" iyz="0.0" izz="0.0151074" />
      <origin rpy="0.0 0.0 0.0" xyz="0.0 -0.024201 0.2125"/>  
      </inertial>
  </link>
 <!--    <inertia ixx="0.0833333 * 8.393 * (3 * 0.06 * 0.06 + 0.56 * 0.56)" ixy="0.0" ixz="0.0"
        iyy="0.0833333 * 8.393 * (3 * 0.06 * 0.06 + 0.56 * 0.56)" iyz="0.0"
        izz="0.5 * 8.393 * 0.06 * 0.06" />-->
  <joint name="elbow_joint" type="revolute">
    <parent link="upper_arm_link"/>
    <child link="forearm_link"/>
    <origin rpy="0.0 0.0 0.0" xyz="0.0 -0.1197 0.425"/>
    <axis xyz="0 1 0"/>
    <limit effort="150.0" lower="-6.2831853" upper="6.2831853" velocity="3.14159265"/>
    <dynamics damping="0.0" friction="0.0"/>
  </joint>
  <transmission name="trans_elbow">
    <type>transmission_interface/SimpleTransmission</type>
    <joint name="elbow_joint">
      <hardwareInterface>hardware_interface/PositionJointInterface</hardwareInterface>
    </joint>
    <actuator name="elbow_motor">
      <mechanicalReduction>1</mechanicalReduction>
    </actuator>
  </transmission>
  <link name="forearm_link">
    <visual>
      <geometry>
        <mesh filename="package://interbotix_xsarm_descriptions/meshes/ur5/visual/Forearm.dae"/>
      </geometry>
    </visual>
    <collision>
      <geometry>
        <mesh filename="package://interbotix_xsarm_descriptions/meshes/ur5/collision/Forearm.dae"/>
      </geometry>
      <!--       <origin rpy="0.0 0.0 0.0" xyz="0.0 0.0 0.196125"/> -->
    </collision>
    <inertial>
      <mass value="2.275"/>
      <origin rpy="0.0 0.0 0.0" xyz="0.0 0.0265 0.11993"/>
       <inertia ixx="0.049443313556" ixy="0.0" ixz="0.0" iyy="0.049443313556" iyz="0.0" izz="0.004095" />
    </inertial>
  </link>
 <!--    <inertia ixx="0.0833333 * 2.275 * (3 * 0.06 * 0.06 + 0.5 * 0.5)" ixy="0.0" ixz="0.0"
        iyy="0.0833333 * 2.275 * (3 * 0.06 * 0.06 + 0.5 * 0.5)" iyz="0.0"
        izz="0.5 * 2.275 * 0.06 * 0.06" /> -->
  <joint name="wrist_1_joint" type="revolute">
    <parent link="forearm_link"/>
    <child link="wrist_1_link"/>
    <origin rpy="0.0 1.570796325 0.0" xyz="0.0 0.0 0.39225"/>
    <axis xyz="0 1 0"/>
    <limit effort="28.0" lower="-3.14159265" upper="4.71" velocity="3.14159265"/>
    <dynamics damping="0.0" friction="0.0"/>
  </joint>
  <transmission name="trans_wrist1_joint">
    <type>transmission_interface/SimpleTransmission</type>
    <joint name="wrist_1_joint">
      <hardwareInterface>hardware_interface/PositionJointInterface</hardwareInterface>
    </joint>
    <actuator name="wrist_1_motor">
      <mechanicalReduction>1</mechanicalReduction>
    </actuator>
  </transmission>
  <link name="wrist_1_link">
    <visual>
      <geometry>
        <mesh filename="package://interbotix_xsarm_descriptions/meshes/ur5/visual/Wrist1.dae"/>
      </geometry>
      <origin rpy="0.0 1.570796325 0.0" xyz="0.0 0.093 0.0"/>
    </visual>
    <collision>
      <geometry>
        <mesh filename="package://interbotix_xsarm_descriptions/meshes/ur5/collision/Wrist1.dae"/>
      </geometry>
      <origin rpy="0.0 1.570796325 0.0" xyz="0.0 0.093 0.0"/>
    </collision>
    <inertial>
      <mass value="1.219"/>
      <origin rpy="0.0 0.0 0.0" xyz="0.0 0.110949 0.01634"/>   
      <inertia ixx="0.11117275553088" ixy="0.0" ixz="0.0" iyy="0.11117275553088" iyz="0.0" izz="0.21942" />
    </inertial>
  </link>
<!--    <inertia ixx="0.0833333 * 1.219 * (3 * 0.6 * 0.6 + 0.12 * 0.12)" ixy="0.0" ixz="0.0"
        iyy="0.0833333 * 1.219 * (3 * 0.6 * 0.6 + 0.12 * 0.12)" iyz="0.0"
        izz="0.5 * 1.219 * 0.6 * 0.6" /> -->
  <joint name="wrist_2_joint" type="revolute">
    <parent link="wrist_1_link"/>
    <child link="wrist_2_link"/>
    <origin rpy="0.0 0.0 0.0" xyz="0.0 0.093 0.0"/>
    <axis xyz="0 0 1"/>
    <limit effort="28.0" lower="-3.14159265" upper="4.71" velocity="3.14159265"/>
    <dynamics damping="0.0" friction="0.0"/>
  </joint>
  <transmission name="trans_wrist2_joint">
    <type>transmission_interface/SimpleTransmission</type>
    <joint name="wrist_2_joint">
      <hardwareInterface>hardware_interface/PositionJointInterface</hardwareInterface>
    </joint>
    <actuator name="wrist_2_motor">
      <mechanicalReduction>1</mechanicalReduction>
    </actuator>
  </transmission>
  <link name="wrist_2_link">
    <visual>
      <geometry>
        <mesh filename="package://interbotix_xsarm_descriptions/meshes/ur5/visual/Wrist2.dae"/>
      </geometry>
      <origin rpy="0.0 0.0 0.0" xyz="0.0 0.0 0.09465"/>
    </visual>
    <collision>
      <geometry>
        <mesh filename="package://interbotix_xsarm_descriptions/meshes/ur5/collision/Wrist2.dae"/>
      </geometry>
      <origin rpy="0.0 0.0 0.0" xyz="0.0 0.0 0.09465"/>
    </collision>
    <inertial>
      <mass value="1.219"/>
      <origin rpy="0.0 0.0 0.0" xyz="0.0 0.0018 0.11099"/>  
      <inertia ixx="0.11117275553088" ixy="0.0" ixz="0.0" iyy="0.11117275553088" iyz="0.0" izz="0.21942" />
    </inertial>
  </link>
<!--    <inertia ixx="0.0833333 * 1.219 * (3 * 0.6 * 0.6 + 0.12 * 0.12)" ixy="0.0" ixz="0.0"
        iyy="0.0833333 * 1.219 * (3 * 0.6 * 0.6 + 0.12 * 0.12)" iyz="0.0"
        izz="0.5 * 1.219 * 0.6 * 0.6" /> -->
  <joint name="wrist_3_joint" type="revolute">
    <parent link="wrist_2_link"/>
    <child link="wrist_3_link"/>
    <origin rpy="0.0 0.0 0.0" xyz="0.0 0.0 0.09465"/>
    <axis xyz="0 1 0"/>
    <limit effort="28.0" lower="-3.14159265" upper="3.14159265" velocity="3.14159265"/>
    <dynamics damping="0.0" friction="0.0"/>
  </joint>
  <transmission name="trans_wrist3_joint">
    <type>transmission_interface/SimpleTransmission</type>
    <joint name="wrist_3_joint">
      <hardwareInterface>hardware_interface/PositionJointInterface</hardwareInterface>
    </joint>
    <actuator name="wrist_3_motor">
      <mechanicalReduction>1</mechanicalReduction>
    </actuator>
  </transmission>
  <link name="wrist_3_link">
    <visual>
      <geometry>
        <mesh filename="package://interbotix_xsarm_descriptions/meshes/ur5/visual/Wrist3.dae"/>
      </geometry>
    </visual>
    <collision>
      <geometry>
        <mesh filename="package://interbotix_xsarm_descriptions/meshes/ur5/collision/Wrist3.dae"/>
      </geometry>
    </collision>
    <inertial>
      <mass value="0.1879"/>
      <origin rpy="0.0 0.0 0.0" xyz="0.0 0.001159 0.0"/>
      <inertia ixx="0.017136473145408" ixy="0.0" ixz="0.0" iyy="0.017136473145408" iyz="0.0" izz="0.033822" />
    </inertial>
  </link>
<!--     <inertia ixx="0.0833333 * 0.1879 * (3 * 0.6 * 0.6 + 0.12 * 0.12)" ixy="0.0" ixz="0.0"
        iyy="0.0833333 * 0.1879 * (3 * 0.6 * 0.6 + 0.12 * 0.12)" iyz="0.0"
        izz="0.5 * 0.1879 * 0.6 * 0.6" />-->

  <joint name="joint0" type="fixed">
    <parent link="wrist_3_link"/>
    <child link="onrobot_rg2_base_link"/>
    <origin rpy="0. 1.5708 1.570796325" xyz="0. 0.0823 0."/>
  </joint>
  
  <link name="onrobot_rg2_base_link">
    <inertial>
      <origin rpy="0 0 0" xyz="0.0 0.0 0.0"/>
      <mass value="0.7"/>
      <inertia ixx="1.0E-03" ixy="1.0E-06" ixz="1.0E-06" iyy="1.0E-03" iyz="1.0E-06" izz="1.0E-03"/>
    </inertial>
    <visual>
      <origin rpy="0 0 0" xyz="0 0 0"/>
      <geometry>
        <mesh filename="package://interbotix_xsarm_descriptions/meshes/ur5/visual/base_link.stl"/>
      </geometry>
      <material name="">
        <color rgba="0.8 0.8 0.8 1"/>
      </material>
    </visual>
    <collision>
      <origin rpy="0 0 0" xyz="0 0 0"/>
      <geometry>
        <mesh filename="package://interbotix_xsarm_descriptions/meshes/ur5/collision/base_link.stl"/>
      </geometry>
    </collision>
  </link>
  <joint name="finger_joint" type="revolute">
    <origin rpy="0 0 0" xyz="0 -0.017178 0.125797"/>
    <parent link="onrobot_rg2_base_link"/>
    <child link="left_outer_knuckle"/>
    <axis xyz="-1 0 0"/>
    <limit effort="1000" lower="-0.558505" upper="0.785398" velocity="100.0"/>
  </joint>
  <transmission name="trans_finger_joint">
    <type>transmission_interface/SimpleTransmission</type>
    <joint name="finger_joint">
      <hardwareInterface>hardware_interface/PositionJointInterface</hardwareInterface>
    </joint>
    <actuator name="finger_motor">
      <mechanicalReduction>1</mechanicalReduction>
    </actuator>
  </transmission>
  <link name="left_outer_knuckle">
    <inertial>
      <origin rpy="0 0 0" xyz="0.0 0.0 0.0"/>
      <mass value="0.05"/>
      <inertia ixx="1.0E-03" ixy="1.0E-06" ixz="1.0E-06" iyy="1.0E-03" iyz="1.0E-06" izz="1.0E-03"/>
    </inertial>
    <visual>
      <origin rpy="0 0 0" xyz="0 0 0"/>
      <geometry>
        <mesh filename="package://interbotix_xsarm_descriptions/meshes/ur5/visual/outer_knuckle.stl"/>
      </geometry>
      <material name="">
        <color rgba="0.8 0.8 0.8 1"/>
      </material>
    </visual>
    <collision>
      <origin rpy="0 0 0" xyz="0 0 0"/>
      <geometry>
        <mesh filename="package://interbotix_xsarm_descriptions/meshes/ur5/collision/outer_knuckle.stl"/>
      </geometry>
    </collision>
  </link>
  <joint name="left_inner_knuckle_joint" type="revolute">
    <origin rpy="0 0 0.0" xyz="0 -0.007678 0.1422970"/>
    <parent link="onrobot_rg2_base_link"/>
    <child link="left_inner_knuckle"/>
    <axis xyz="1 0 0"/>
    <limit effort="1000" lower="-0.785398" upper="0.785398" velocity="100.0"/>
    <mimic joint="finger_joint" multiplier="-1" offset="0"/>
  </joint>
  <transmission name="trans_left_inner_knuckle_joint">
    <type>transmission_interface/SimpleTransmission</type>
    <joint name="left_inner_knuckle_joint">
      <hardwareInterface>hardware_interface/PositionJointInterface</hardwareInterface>
    </joint>
    <actuator name="left_inner_knuckle_motor">
      <mechanicalReduction>1</mechanicalReduction>
    </actuator>
  </transmission>
  <link name="left_inner_knuckle">
    <inertial>
      <origin rpy="0 0 0" xyz="0.0 0.0 0.0"/>
      <mass value="0.05"/>
      <inertia ixx="1.0E-03" ixy="1.0E-06" ixz="1.0E-06" iyy="1.0E-03" iyz="1.0E-06" izz="1.0E-03"/>
    </inertial>
    <visual>
      <origin rpy="0 0 0" xyz="0 0 0"/>
      <geometry>
        <mesh filename="package://interbotix_xsarm_descriptions/meshes/ur5/visual/inner_knuckle.stl"/>
      </geometry>
      <material name="">
        <color rgba="0.8 0.8 0.8 1"/>
      </material>
    </visual>
    <collision>
      <origin rpy="0 0 0" xyz="0 0 0"/>
      <geometry>
        <mesh filename="package://interbotix_xsarm_descriptions/meshes/ur5/collision/inner_knuckle.stl"/>
      </geometry>
    </collision>
  </link>
  <joint name="left_inner_finger_joint" type="revolute">
    <origin rpy="0 0 0" xyz="0 -0.039592 0.038177000000000016"/>
    <parent link="left_outer_knuckle"/>
    <child link="left_inner_finger"/>
    <axis xyz="1 0 0"/>
    <limit effort="1000" lower="-0.872665" upper="0.872665" velocity="100.0"/>
    <mimic joint="finger_joint" multiplier="1" offset="0"/>
  </joint>
    <transmission name="trans_left_inner_finger_joint">
    <type>transmission_interface/SimpleTransmission</type>
    <joint name="left_inner_finger_joint">
      <hardwareInterface>hardware_interface/PositionJointInterface</hardwareInterface>
    </joint>
    <actuator name="left_inner_finger_motor">
      <mechanicalReduction>1</mechanicalReduction>
    </actuator>
  </transmission>
  <link name="left_inner_finger">
    <inertial>
      <origin rpy="0 0 0" xyz="0.0 0.0 0.0"/>
      <mass value="0.05"/>
      <inertia ixx="1.0E-03" ixy="1.0E-06" ixz="1.0E-06" iyy="1.0E-03" iyz="1.0E-06" izz="1.0E-03"/>
    </inertial>
    <visual>
      <origin rpy="0 0 0" xyz="0 0 0"/>
      <geometry>
        <mesh filename="package://interbotix_xsarm_descriptions/meshes/ur5/visual/inner_finger.stl"/>
      </geometry>
      <material name="">
        <color rgba="0.1 0.1 0.1 1"/>
      </material>
    </visual>
    <collision>
      <origin rpy="0 0 0" xyz="0 0 0"/>
      <geometry>
        <mesh filename="package://interbotix_xsarm_descriptions/meshes/ur5/collision/inner_finger.stl"/>
      </geometry>
    </collision>
  </link>
  <joint name="right_outer_knuckle_joint" type="revolute">
    <origin rpy="0 0 3.141592653589793" xyz="0 0.017178 0.125797"/>
    <parent link="onrobot_rg2_base_link"/>
    <child link="right_outer_knuckle"/>
    <axis xyz="1 0 0"/>
    <limit effort="1000" lower="-0.785398" upper="0.785398" velocity="100.0"/>
    <mimic joint="finger_joint" multiplier="-1" offset="0"/>
  </joint>
  <transmission name="trans_right_outer_knuckle_joint">
    <type>transmission_interface/SimpleTransmission</type>
    <joint name="right_outer_knuckle_joint">
      <hardwareInterface>hardware_interface/PositionJointInterface</hardwareInterface>
    </joint>
    <actuator name="right_outer_knuckle_motor">
      <mechanicalReduction>1</mechanicalReduction>
    </actuator>
  </transmission>
  <link name="right_outer_knuckle">
    <inertial>
      <origin rpy="0 0 0" xyz="0.0 0.0 0.0"/>
      <mass value="0.05"/>
      <inertia ixx="1.0E-03" ixy="1.0E-06" ixz="1.0E-06" iyy="1.0E-03" iyz="1.0E-06" izz="1.0E-03"/>
    </inertial>
    <visual>
      <origin rpy="0 0 0" xyz="0 0 0"/>
      <geometry>
        <mesh filename="package://interbotix_xsarm_descriptions/meshes/ur5/visual/outer_knuckle.stl"/>
      </geometry>
      <material name="">
        <color rgba="0.8 0.8 0.8 1"/>
      </material>
    </visual>
    <collision>
      <origin rpy="0 0 0" xyz="0 0 0"/>
      <geometry>
        <mesh filename="package://interbotix_xsarm_descriptions/meshes/ur5/collision/outer_knuckle.stl"/>
      </geometry>
    </collision>
  </link>
  <joint name="right_inner_knuckle_joint" type="revolute">
    <origin rpy="0 0 -3.141592653589793" xyz="0 0.007678 0.1422970"/>
    <parent link="onrobot_rg2_base_link"/>
    <child link="right_inner_knuckle"/>
    <axis xyz="1 0 0"/>
    <limit effort="1000" lower="-0.785398" upper="0.785398" velocity="100.0"/>
    <mimic joint="finger_joint" multiplier="-1" offset="0"/>
  </joint>
  <transmission name="trans_right_inner_knuckle_joint">
    <type>transmission_interface/SimpleTransmission</type>
    <joint name="right_inner_knuckle_joint">
      <hardwareInterface>hardware_interface/PositionJointInterface</hardwareInterface>
    </joint>
    <actuator name="right_inner_knuckle_motor">
      <mechanicalReduction>1</mechanicalReduction>
    </actuator>
  </transmission>
  <link name="right_inner_knuckle">
    <inertial>
      <origin rpy="0 0 0" xyz="0.0 0.0 0.0"/>
      <mass value="0.05"/>
      <inertia ixx="1.0E-03" ixy="1.0E-06" ixz="1.0E-06" iyy="1.0E-03" iyz="1.0E-06" izz="1.0E-03"/>
    </inertial>
    <visual>
      <origin rpy="0 0 0" xyz="0 0 0"/>
      <geometry>
        <mesh filename="package://interbotix_xsarm_descriptions/meshes/ur5/visual/inner_knuckle.stl"/>
      </geometry>
      <material name="">
        <color rgba="0.8 0.8 0.8 1"/>
      </material>
    </visual>
    <collision>
      <origin rpy="0 0 0" xyz="0 0 0"/>
      <geometry>
        <mesh filename="package://interbotix_xsarm_descriptions/meshes/ur5/collision/inner_knuckle.stl"/>
      </geometry>
    </collision>
  </link>
  <joint name="right_inner_finger_joint" type="revolute">
    <origin rpy="0 0 0" xyz="0 -0.039592 0.038177000000000016"/>
    <parent link="right_outer_knuckle"/>
    <child link="right_inner_finger"/>
    <axis xyz="1 0 0"/>
    <limit effort="1000" lower="-0.872665" upper="0.872665" velocity="100.0"/>
    <mimic joint="finger_joint" multiplier="1" offset="0"/>
  </joint>
    <transmission name="trans_right_inner_finger_joint">
    <type>transmission_interface/SimpleTransmission</type>
    <joint name="right_inner_finger_joint">
      <hardwareInterface>hardware_interface/PositionJointInterface</hardwareInterface>
    </joint>
    <actuator name="right_inner_finger_motor">
      <mechanicalReduction>1</mechanicalReduction>
    </actuator>
  </transmission>

  <link name="right_inner_finger">
    <inertial>
      <origin rpy="0 0 0" xyz="0.0 0.0 0.0"/>
      <mass value="0.05"/>
      <inertia ixx="1.0E-03" ixy="1.0E-06" ixz="1.0E-06" iyy="1.0E-03" iyz="1.0E-06" izz="1.0E-03"/>
    </inertial>
    <visual>
      <origin rpy="0 0 0" xyz="0 0 0"/>
      <geometry>
        <mesh filename="package://interbotix_xsarm_descriptions/meshes/ur5/visual/inner_finger.stl"/>
      </geometry>
      <material name="">
        <color rgba="0.1 0.1 0.1 1"/>
      </material>
    </visual>
    <collision>
      <origin rpy="0 0 0" xyz="0 0 0"/>
      <geometry>
        <mesh filename="package://interbotix_xsarm_descriptions/meshes/ur5/collision/inner_finger.stl"/>
      </geometry>
    </collision>
  </link>
  
  
 <gazebo>
   <plugin name="gazebo_grasp_fix" filename="libgazebo_grasp_fix.so">
        <arm>
           <arm_name>ur5_arm_robot</arm_name>
           <palm_link>wrist_3_link</palm_link>
           <gripper_link> left_outer_knuckle </gripper_link>
           <gripper_link> right_outer_knuckle </gripper_link>
           <gripper_link> left_inner_knuckle </gripper_link>
           <gripper_link> right_inner_knuckle </gripper_link>
           <gripper_link> left_inner_finger </gripper_link>
           <gripper_link> right_inner_finger </gripper_link>
        </arm>
       <forces_angle_tolerance>100</forces_angle_tolerance>
       <update_rate>4</update_rate>
       <grip_count_threshold>4</grip_count_threshold>
       <max_grip_count>8</max_grip_count>
       <release_tolerance>0.005</release_tolerance>
       <disable_collisions_on_attach>false</disable_collisions_on_attach>
       <contact_topic>__default_topic__</contact_topic>
    </plugin>
 </gazebo>
  
  
</robot>


